Workbook

Sheet Summary
A1: OWASP ASVS 5.0 – Compliance Tracker
A5: Chapter | B5: Total Reqs | C5: L1 Total | D5: L1 Compliant | E5: L1 % | F5: L2 Total | G5: L2 Compliant | H5: L2 % | I5: L3 Total | J5: L3 Compliant | K5: L3 % | L5: Overall Compliant | M5: Overall %
A6: V1 – Encoding and Sanitization | B6: 30 | C6: 8 | D6: =COUNTIFS('V1 - Encoding and Sanitization'!$F$2:$F$36,"Compliant",'V1 - Encoding and Sanitization'!$E$2:$E$36,1) | E6: =IF(C6=0,"",D6/C6) | F6: 19 | G6: =COUNTIFS('V1 - Encoding and Sanitization'!$F$2:$F$36,"Compliant",'V1 - Encoding and Sanitization'!$E$2:$E$36,2) | H6: =IF(F6=0,"",G6/F6) | I6: 3 | J6: =COUNTIFS('V1 - Encoding and Sanitization'!$F$2:$F$36,"Compliant",'V1 - Encoding and Sanitization'!$E$2:$E$36,3) | K6: =IF(I6=0,"",J6/I6) | L6: =COUNTIF('V1 - Encoding and Sanitization'!$F$2:$F$36,"Compliant") | M6: =IF(B6=0,"",L6/B6)
A7: V2 – Validation and Business Logic | B7: 13 | C7: 4 | D7: =COUNTIFS('V2 - Validation and Business Lo'!$F$2:$F$18,"Compliant",'V2 - Validation and Business Lo'!$E$2:$E$18,1) | E7: =IF(C7=0,"",D7/C7) | F7: 7 | G7: =COUNTIFS('V2 - Validation and Business Lo'!$F$2:$F$18,"Compliant",'V2 - Validation and Business Lo'!$E$2:$E$18,2) | H7: =IF(F7=0,"",G7/F7) | I7: 2 | J7: =COUNTIFS('V2 - Validation and Business Lo'!$F$2:$F$18,"Compliant",'V2 - Validation and Business Lo'!$E$2:$E$18,3) | K7: =IF(I7=0,"",J7/I7) | L7: =COUNTIF('V2 - Validation and Business Lo'!$F$2:$F$18,"Compliant") | M7: =IF(B7=0,"",L7/B7)
A8: V3 – Web Frontend Security | B8: 31 | C8: 8 | D8: =COUNTIFS('V3 - Web Frontend Security'!$F$2:$F$39,"Compliant",'V3 - Web Frontend Security'!$E$2:$E$39,1) | E8: =IF(C8=0,"",D8/C8) | F8: 11 | G8: =COUNTIFS('V3 - Web Frontend Security'!$F$2:$F$39,"Compliant",'V3 - Web Frontend Security'!$E$2:$E$39,2) | H8: =IF(F8=0,"",G8/F8) | I8: 12 | J8: =COUNTIFS('V3 - Web Frontend Security'!$F$2:$F$39,"Compliant",'V3 - Web Frontend Security'!$E$2:$E$39,3) | K8: =IF(I8=0,"",J8/I8) | L8: =COUNTIF('V3 - Web Frontend Security'!$F$2:$F$39,"Compliant") | M8: =IF(B8=0,"",L8/B8)
A9: V4 – API and Web Service | B9: 16 | C9: 2 | D9: =COUNTIFS('V4 - API and Web Service'!$F$2:$F$21,"Compliant",'V4 - API and Web Service'!$E$2:$E$21,1) | E9: =IF(C9=0,"",D9/C9) | F9: 8 | G9: =COUNTIFS('V4 - API and Web Service'!$F$2:$F$21,"Compliant",'V4 - API and Web Service'!$E$2:$E$21,2) | H9: =IF(F9=0,"",G9/F9) | I9: 6 | J9: =COUNTIFS('V4 - API and Web Service'!$F$2:$F$21,"Compliant",'V4 - API and Web Service'!$E$2:$E$21,3) | K9: =IF(I9=0,"",J9/I9) | L9: =COUNTIF('V4 - API and Web Service'!$F$2:$F$21,"Compliant") | M9: =IF(B9=0,"",L9/B9)
A10: V5 – File Handling | B10: 13 | C10: 4 | D10: =COUNTIFS('V5 - File Handling'!$F$2:$F$18,"Compliant",'V5 - File Handling'!$E$2:$E$18,1) | E10: =IF(C10=0,"",D10/C10) | F10: 5 | G10: =COUNTIFS('V5 - File Handling'!$F$2:$F$18,"Compliant",'V5 - File Handling'!$E$2:$E$18,2) | H10: =IF(F10=0,"",G10/F10) | I10: 4 | J10: =COUNTIFS('V5 - File Handling'!$F$2:$F$18,"Compliant",'V5 - File Handling'!$E$2:$E$18,3) | K10: =IF(I10=0,"",J10/I10) | L10: =COUNTIF('V5 - File Handling'!$F$2:$F$18,"Compliant") | M10: =IF(B10=0,"",L10/B10)
A11: V6 – Authentication | B11: 47 | C11: 13 | D11: =COUNTIFS('V6 - Authentication'!$F$2:$F$56,"Compliant",'V6 - Authentication'!$E$2:$E$56,1) | E11: =IF(C11=0,"",D11/C11) | F11: 22 | G11: =COUNTIFS('V6 - Authentication'!$F$2:$F$56,"Compliant",'V6 - Authentication'!$E$2:$E$56,2) | H11: =IF(F11=0,"",G11/F11) | I11: 12 | J11: =COUNTIFS('V6 - Authentication'!$F$2:$F$56,"Compliant",'V6 - Authentication'!$E$2:$E$56,3) | K11: =IF(I11=0,"",J11/I11) | L11: =COUNTIF('V6 - Authentication'!$F$2:$F$56,"Compliant") | M11: =IF(B11=0,"",L11/B11)
A12: V7 – Session Management | B12: 19 | C12: 6 | D12: =COUNTIFS('V7 - Session Management'!$F$2:$F$26,"Compliant",'V7 - Session Management'!$E$2:$E$26,1) | E12: =IF(C12=0,"",D12/C12) | F12: 12 | G12: =COUNTIFS('V7 - Session Management'!$F$2:$F$26,"Compliant",'V7 - Session Management'!$E$2:$E$26,2) | H12: =IF(F12=0,"",G12/F12) | I12: 1 | J12: =COUNTIFS('V7 - Session Management'!$F$2:$F$26,"Compliant",'V7 - Session Management'!$E$2:$E$26,3) | K12: =IF(I12=0,"",J12/I12) | L12: =COUNTIF('V7 - Session Management'!$F$2:$F$26,"Compliant") | M12: =IF(B12=0,"",L12/B12)
A13: V8 – Authorization | B13: 13 | C13: 4 | D13: =COUNTIFS('V8 - Authorization'!$F$2:$F$18,"Compliant",'V8 - Authorization'!$E$2:$E$18,1) | E13: =IF(C13=0,"",D13/C13) | F13: 3 | G13: =COUNTIFS('V8 - Authorization'!$F$2:$F$18,"Compliant",'V8 - Authorization'!$E$2:$E$18,2) | H13: =IF(F13=0,"",G13/F13) | I13: 6 | J13: =COUNTIFS('V8 - Authorization'!$F$2:$F$18,"Compliant",'V8 - Authorization'!$E$2:$E$18,3) | K13: =IF(I13=0,"",J13/I13) | L13: =COUNTIF('V8 - Authorization'!$F$2:$F$18,"Compliant") | M13: =IF(B13=0,"",L13/B13)
A14: V9 – Self-contained Tokens | B14: 7 | C14: 4 | D14: =COUNTIFS('V9 - Self-contained Tokens'!$F$2:$F$10,"Compliant",'V9 - Self-contained Tokens'!$E$2:$E$10,1) | E14: =IF(C14=0,"",D14/C14) | F14: 3 | G14: =COUNTIFS('V9 - Self-contained Tokens'!$F$2:$F$10,"Compliant",'V9 - Self-contained Tokens'!$E$2:$E$10,2) | H14: =IF(F14=0,"",G14/F14) | I14: 0 | J14: N/A | K14: N/A | L14: =COUNTIF('V9 - Self-contained Tokens'!$F$2:$F$10,"Compliant") | M14: =IF(B14=0,"",L14/B14)
A15: V10 – OAuth and OIDC | B15: 36 | C15: 5 | D15: =COUNTIFS('V10 - OAuth and OIDC'!$F$2:$F$44,"Compliant",'V10 - OAuth and OIDC'!$E$2:$E$44,1) | E15: =IF(C15=0,"",D15/C15) | F15: 24 | G15: =COUNTIFS('V10 - OAuth and OIDC'!$F$2:$F$44,"Compliant",'V10 - OAuth and OIDC'!$E$2:$E$44,2) | H15: =IF(F15=0,"",G15/F15) | I15: 7 | J15: =COUNTIFS('V10 - OAuth and OIDC'!$F$2:$F$44,"Compliant",'V10 - OAuth and OIDC'!$E$2:$E$44,3) | K15: =IF(I15=0,"",J15/I15) | L15: =COUNTIF('V10 - OAuth and OIDC'!$F$2:$F$44,"Compliant") | M15: =IF(B15=0,"",L15/B15)
A16: V11 – Cryptography | B16: 24 | C16: 3 | D16: =COUNTIFS('V11 - Cryptography'!$F$2:$F$32,"Compliant",'V11 - Cryptography'!$E$2:$E$32,1) | E16: =IF(C16=0,"",D16/C16) | F16: 11 | G16: =COUNTIFS('V11 - Cryptography'!$F$2:$F$32,"Compliant",'V11 - Cryptography'!$E$2:$E$32,2) | H16: =IF(F16=0,"",G16/F16) | I16: 10 | J16: =COUNTIFS('V11 - Cryptography'!$F$2:$F$32,"Compliant",'V11 - Cryptography'!$E$2:$E$32,3) | K16: =IF(I16=0,"",J16/I16) | L16: =COUNTIF('V11 - Cryptography'!$F$2:$F$32,"Compliant") | M16: =IF(B16=0,"",L16/B16)
A17: V12 – Secure Communication | B17: 12 | C17: 3 | D17: =COUNTIFS('V12 - Secure Communication'!$F$2:$F$16,"Compliant",'V12 - Secure Communication'!$E$2:$E$16,1) | E17: =IF(C17=0,"",D17/C17) | F17: 6 | G17: =COUNTIFS('V12 - Secure Communication'!$F$2:$F$16,"Compliant",'V12 - Secure Communication'!$E$2:$E$16,2) | H17: =IF(F17=0,"",G17/F17) | I17: 3 | J17: =COUNTIFS('V12 - Secure Communication'!$F$2:$F$16,"Compliant",'V12 - Secure Communication'!$E$2:$E$16,3) | K17: =IF(I17=0,"",J17/I17) | L17: =COUNTIF('V12 - Secure Communication'!$F$2:$F$16,"Compliant") | M17: =IF(B17=0,"",L17/B17)
A18: V13 – Configuration | B18: 21 | C18: 1 | D18: =COUNTIFS('V13 - Configuration'!$F$2:$F$26,"Compliant",'V13 - Configuration'!$E$2:$E$26,1) | E18: =IF(C18=0,"",D18/C18) | F18: 12 | G18: =COUNTIFS('V13 - Configuration'!$F$2:$F$26,"Compliant",'V13 - Configuration'!$E$2:$E$26,2) | H18: =IF(F18=0,"",G18/F18) | I18: 8 | J18: =COUNTIFS('V13 - Configuration'!$F$2:$F$26,"Compliant",'V13 - Configuration'!$E$2:$E$26,3) | K18: =IF(I18=0,"",J18/I18) | L18: =COUNTIF('V13 - Configuration'!$F$2:$F$26,"Compliant") | M18: =IF(B18=0,"",L18/B18)
A19: V14 – Data Protection | B19: 13 | C19: 2 | D19: =COUNTIFS('V14 - Data Protection'!$F$2:$F$17,"Compliant",'V14 - Data Protection'!$E$2:$E$17,1) | E19: =IF(C19=0,"",D19/C19) | F19: 7 | G19: =COUNTIFS('V14 - Data Protection'!$F$2:$F$17,"Compliant",'V14 - Data Protection'!$E$2:$E$17,2) | H19: =IF(F19=0,"",G19/F19) | I19: 4 | J19: =COUNTIFS('V14 - Data Protection'!$F$2:$F$17,"Compliant",'V14 - Data Protection'!$E$2:$E$17,3) | K19: =IF(I19=0,"",J19/I19) | L19: =COUNTIF('V14 - Data Protection'!$F$2:$F$17,"Compliant") | M19: =IF(B19=0,"",L19/B19)
A20: V15 – Secure Coding and Architecture | B20: 21 | C20: 3 | D20: =COUNTIFS('V15 - Secure Coding and Archite'!$F$2:$F$26,"Compliant",'V15 - Secure Coding and Archite'!$E$2:$E$26,1) | E20: =IF(C20=0,"",D20/C20) | F20: 10 | G20: =COUNTIFS('V15 - Secure Coding and Archite'!$F$2:$F$26,"Compliant",'V15 - Secure Coding and Archite'!$E$2:$E$26,2) | H20: =IF(F20=0,"",G20/F20) | I20: 8 | J20: =COUNTIFS('V15 - Secure Coding and Archite'!$F$2:$F$26,"Compliant",'V15 - Secure Coding and Archite'!$E$2:$E$26,3) | K20: =IF(I20=0,"",J20/I20) | L20: =COUNTIF('V15 - Secure Coding and Archite'!$F$2:$F$26,"Compliant") | M20: =IF(B20=0,"",L20/B20)
A21: V16 – Security Logging and Error Handling | B21: 17 | C21: 0 | D21: N/A | E21: N/A | F21: 16 | G21: =COUNTIFS('V16 - Security Logging and Erro'!$F$2:$F$23,"Compliant",'V16 - Security Logging and Erro'!$E$2:$E$23,2) | H21: =IF(F21=0,"",G21/F21) | I21: 1 | J21: =COUNTIFS('V16 - Security Logging and Erro'!$F$2:$F$23,"Compliant",'V16 - Security Logging and Erro'!$E$2:$E$23,3) | K21: =IF(I21=0,"",J21/I21) | L21: =COUNTIF('V16 - Security Logging and Erro'!$F$2:$F$23,"Compliant") | M21: =IF(B21=0,"",L21/B21)
A22: V17 – WebRTC | B22: 12 | C22: 0 | D22: N/A | E22: N/A | F22: 7 | G22: =COUNTIFS('V17 - WebRTC'!$F$2:$F$16,"Compliant",'V17 - WebRTC'!$E$2:$E$16,2) | H22: =IF(F22=0,"",G22/F22) | I22: 5 | J22: =COUNTIFS('V17 - WebRTC'!$F$2:$F$16,"Compliant",'V17 - WebRTC'!$E$2:$E$16,3) | K22: =IF(I22=0,"",J22/I22) | L22: =COUNTIF('V17 - WebRTC'!$F$2:$F$16,"Compliant") | M22: =IF(B22=0,"",L22/B22)
A23: TOTAL | B23: =SUM(B6:B22) | C23: =SUM(C6:C22) | D23: =SUM(D6:D22) | E23: =IFERROR(AVERAGE(E6:E22),"") | F23: =SUM(F6:F22) | G23: =SUM(G6:G22) | H23: =IFERROR(AVERAGE(H6:H22),"") | I23: =SUM(I6:I22) | J23: =SUM(J6:J22) | K23: =IFERROR(AVERAGE(K6:K22),"") | L23: =SUM(L6:L22) | M23: =IFERROR(AVERAGE(M6:M22),"")

Sheet ASVS DX Guide
A1: ASVS Tracker DX Guide
A2: What is automated? | B2: make asvs-tracker runs evidence tests, copies the source workbook, scans repository evidence, infers each ASVS row, and writes this filled workbook.
A3: Input source | B3: The Excel template is the source of ASVS rows. The markdown tracker is not read or required.
A4: Important limitation | B4: The automation is deterministic: it can infer from tests, source, configuration, and build artifacts, but a new control may need a new targeted test/evidence rule before it becomes Compliant.
A6: Status | B6: Meaning | C6: When generated | D6: Next action
A7: Compliant | B7: The row has matching implementation/configuration/build evidence and the evidence test run passed. | C7: Generated when direct automated evidence or source evidence matches the ASVS row. | D7: Keep make asvs-tracker passing and update tests when scope changes.
A8: Planned | B8: The row is relevant but not yet strongly proven by repository evidence. | C8: Generated when the row has no direct matching evidence or only weak/reference evidence. | D8: Implement the control or add a targeted test/evidence rule.
A9: N/A | B9: The row is outside the current backend/API scope. | C9: Generated for absent technologies such as frontend DOM, OAuth/OIDC, GraphQL, XML/SOAP, WebRTC, or file upload surfaces. | D9: Revisit if that technology enters scope.
A11: DX column | B11: Purpose | C11: Example
A12: DX Status Meaning | B12: Plain-language explanation of the generated status. | C12: Compliant means repository evidence matched and tests passed.
A13: Evidence Type | B13: Shows whether support is automated, referenced, scope-based, or missing. | C13: Automated repository evidence
A14: Automated Evidence | B14: Mapped tests, code features, or build artifacts supporting the row. | C14: RbacIntegrationTest; Spring method security and RBAC annotations detected
A15: Evidence Source | B15: The security topic inferred from ASVS text and SR/AC references. | C15: RBAC roles and endpoint isolation
A16: Next Action | B16: What to do to move the row forward. | C16: Add implementation/tests that directly prove this ASVS row.
A18: Recommended commands | B18: make asvs-tracker | C18: Runs tests and regenerates the filled Excel.
A19: Recommended commands | B19: make asvs-fill | C19: Regenerates Excel from existing reports without rerunning tests.

Sheet V1 - Encoding and Sanitization
A1: Section ID | B1: Section Name | C1: Req ID | D1: Description | E1: Level | F1: Status | G1: Observations | H1: Reference / Link | I1: DX Status Meaning | J1: Evidence Type | K1: Automated Evidence | L1: Evidence Source | M1: Next Action
A2: V1.1 | B2: Encoding and Sanitization Architecture
A3: V1.1 | B3: Encoding and Sanitization Architecture | C3: V1.1.1 | D3: Verify that input is decoded or unescaped into a canonical form only once, it is only decoded when encoded data in that form is expected, and that this is done before processing the input further, for example it is not performed after input validation or sanitization. | E3: 2 | F3: Compliant | G3: Automatically marked compliant from passing evidence: server-side price enforcement; stock limit validation; input shape/range validation; unknown-field rejection; payload/request limit coverage. | H3: SR-24; SR-25; SR-28; SR-29; SR-30; SaleServiceTest; AbuseCaseRegressionTest; SlotServiceTest; ControllerIntegrationTests; SystemFunctionalTests; ControllerUnitTests; GlobalExceptionHandlerTest; application.properties; Bean Validation and request-shape controls detected | I3: Automatically inferred as implemented or justified from passing tests, source code, configuration, or build artifacts. | J3: Automated repository evidence | K3: SaleServiceTest; AbuseCaseRegressionTest; SlotServiceTest; ControllerIntegrationTests; SystemFunctionalTests; ControllerUnitTests; GlobalExceptionHandlerTest; application.properties; Bean Validation and request-shape controls detected | L3: server-side price enforcement; stock limit validation; input shape/range validation; unknown-field rejection; payload/request limit coverage | M3: Keep make asvs-tracker passing; reassess if code, tests, or scope changes.
A4: V1.1 | B4: Encoding and Sanitization Architecture | C4: V1.1.2 | D4: Verify that the application performs output encoding and escaping either as a final step before being used by the interpreter for which it is intended or by the interpreter itself. | E4: 2 | F4: Compliant | G4: Automatically marked compliant from passing evidence: DTO response boundaries and unknown-field rejection. | H4: SR-16; ControllerUnitTests; GlobalExceptionHandlerTest | I4: Automatically inferred as implemented or justified from passing tests, source code, configuration, or build artifacts. | J4: Automated repository evidence | K4: ControllerUnitTests; GlobalExceptionHandlerTest | L4: DTO response boundaries and unknown-field rejection | M4: Keep make asvs-tracker passing; reassess if code, tests, or scope changes.
A5: V1.2 | B5: Injection Prevention
A6: V1.2 | B6: Injection Prevention | C6: V1.2.1 | D6: Verify that output encoding for an HTTP response, HTML document, or XML document is relevant for the context required, such as encoding the relevant characters for HTML elements, HTML attributes, HTML comments, CSS, or HTTP header fields, to avoid changing the message or document structure. | E6: 1 | F6: N/A | G6: Automatically marked out of scope: No browser-rendered frontend surface is present in this repository. | H6: Automated scope inference | I6: Out of scope for VendNet as currently implemented, or the requirement does not apply to this REST API/backend. | J6: Scope inference | K6: Not required for current backend scope. | L6: No browser-rendered frontend surface is present in this repository. | M6: Revisit if the application scope changes.
A7: V1.2 | B7: Injection Prevention | C7: V1.2.2 | D7: Verify that when dynamically building URLs, untrusted data is encoded according to its context (e.g., URL encoding or base64url encoding for query or path parameters). Ensure that only safe URL protocols are permitted (e.g., disallow javascript: or data:). | E7: 1 | F7: N/A | G7: Automatically marked out of scope: No browser-rendered frontend surface is present in this repository. | H7: Automated scope inference | I7: Out of scope for VendNet as currently implemented, or the requirement does not apply to this REST API/backend. | J7: Scope inference | K7: Not required for current backend scope. | L7: No browser-rendered frontend surface is present in this repository. | M7: Revisit if the application scope changes.
A8: V1.2 | B8: Injection Prevention | C8: V1.2.3 | D8: Verify that output encoding or escaping is used when dynamically building JavaScript content (including JSON), to avoid changing the message or document structure (to avoid JavaScript and JSON injection). | E8: 1 | F8: N/A | G8: Automatically marked out of scope: No browser-rendered frontend surface is present in this repository. | H8: Automated scope inference | I8: Out of scope for VendNet as currently implemented, or the requirement does not apply to this REST API/backend. | J8: Scope inference | K8: Not required for current backend scope. | L8: No browser-rendered frontend surface is present in this repository. | M8: Revisit if the application scope changes.
A9: V1.2 | B9: Injection Prevention | C9: V1.2.4 | D9: Verify that data selection or database queries (e.g., SQL, HQL, NoSQL, Cypher) use parameterized queries, ORMs, entity frameworks, or are otherwise protected from SQL Injection and other database injection attacks. This is also relevant when writing stored procedures. | E9: 1 | F9: Compliant | G9: Automatically marked compliant from passing evidence: SQL injection regression and taint checks; SQL injection abuse-case regression. | H9: SR-09; AC-05; AbuseCaseRegressionTest; IastIntegrationTest | I9: Automatically inferred as implemented or justified from passing tests, source code, configuration, or build artifacts. | J9: Automated repository evidence | K9: AbuseCaseRegressionTest; IastIntegrationTest | L9: SQL injection regression and taint checks; SQL injection abuse-case regression | M9: Keep make asvs-tracker passing; reassess if code, tests, or scope changes.
A10: V1.2 | B10: Injection Prevention | C10: V1.2.5 | D10: Verify that the application protects against OS command injection and that operating system calls use parameterized OS queries or use contextual command line output encoding. | E10: 1 | F10: Compliant | G10: Automatically marked compliant from passing evidence: SQL injection regression and taint checks; SQL injection abuse-case regression. | H10: SR-09; AC-05; AbuseCaseRegressionTest; IastIntegrationTest | I10: Automatically inferred as implemented or justified from passing tests, source code, configuration, or build artifacts. | J10: Automated repository evidence | K10: AbuseCaseRegressionTest; IastIntegrationTest | L10: SQL injection regression and taint checks; SQL injection abuse-case regression | M10: Keep make asvs-tracker passing; reassess if code, tests, or scope changes.
A11: V1.2 | B11: Injection Prevention | C11: V1.2.6 | D11: Verify that the application protects against LDAP injection vulnerabilities, or that specific security controls to prevent LDAP injection have been implemented. | E11: 2 | F11: Compliant | G11: Automatically marked compliant from passing evidence: SQL injection regression and taint checks; SQL injection abuse-case regression. | H11: SR-09; AC-05; AbuseCaseRegressionTest; IastIntegrationTest | I11: Automatically inferred as implemented or justified from passing tests, source code, configuration, or build artifacts. | J11: Automated repository evidence | K11: AbuseCaseRegressionTest; IastIntegrationTest | L11: SQL injection regression and taint checks; SQL injection abuse-case regression | M11: Keep make asvs-tracker passing; reassess if code, tests, or scope changes.
A12: V1.2 | B12: Injection Prevention | C12: V1.2.7 | D12: Verify that the application is protected against XPath injection attacks by using query parameterization or precompiled queries. | E12: 2 | F12: Compliant | G12: Automatically marked compliant from passing evidence: SQL injection regression and taint checks; SQL injection abuse-case regression; path traversal and report sandboxing; unsafe path/link handling; path traversal abuse-case regression. | H12: SR-09; AC-05; SR-26; SR-27; AC-06; AbuseCaseRegressionTest; IastIntegrationTest; PathValidatorImplTest; ReportDirectoryServiceImplTest; path validation and report sandbox code detected | I12: Automatically inferred as implemented or justified from passing tests, source code, configuration, or build artifacts. | J12: Automated repository evidence | K12: AbuseCaseRegressionTest; IastIntegrationTest; PathValidatorImplTest; ReportDirectoryServiceImplTest; path validation and report sandbox code detected | L12: SQL injection regression and taint checks; SQL injection abuse-case regression; path traversal and report sandboxing; unsafe path/link handling; path traversal abuse-case regression | M12: Keep make asvs-tracker passing; reassess if code, tests, or scope changes.
A13: V1.2 | B13: Injection Prevention | C13: V1.2.8 | D13: Verify that LaTeX processors are configured securely (such as not using the "--shell-escape" flag) and an allowlist of commands is used to prevent LaTeX injection attacks. | E13: 2 | F13: Compliant | G13: Automatically marked compliant from passing evidence: SQL injection regression and taint checks; SQL injection abuse-case regression. | H13: SR-09; AC-05; AbuseCaseRegressionTest; IastIntegrationTest | I13: Automatically inferred as implemented or justified from passing tests, source code, configuration, or build artifacts. | J13: Automated repository evidence | K13: AbuseCaseRegressionTest; IastIntegrationTest | L13: SQL injection regression and taint checks; SQL injection abuse-case regression | M13: Keep make asvs-tracker passing; reassess if code, tests, or scope changes.
A14: V1.2 | B14: Injection Prevention | C14: V1.2.9 | D14: Verify that the application escapes special characters in regular expressions (typically using a backslash) to prevent them from being misinterpreted as metacharacters. | E14: 2 | F14: Compliant | G14: Automatically marked compliant from passing evidence: path traversal and report sandboxing. | H14: SR-26; PathValidatorImplTest; ReportDirectoryServiceImplTest; AbuseCaseRegressionTest; path validation and report sandbox code detected | I14: Automatically inferred as implemented or justified from passing tests, source code, configuration, or build artifacts. | J14: Automated repository evidence | K14: PathValidatorImplTest; ReportDirectoryServiceImplTest; AbuseCaseRegressionTest; path validation and report sandbox code detected | L14: path traversal and report sandboxing | M14: Keep make asvs-tracker passing; reassess if code, tests, or scope changes.
A15: V1.2 | B15: Injection Prevention | C15: V1.2.10 | D15: Verify that the application is protected against CSV and Formula Injection. The application must follow the escaping rules defined in RFC 4180 sections 2.6 and 2.7 when exporting CSV content. Additionally, when exporting to CSV or other spreadsheet formats (such as XLS, XLSX, or ODF), special characters (including '=', '+', '-', '@', '\t' (tab), and '\0' (null character)) must be escaped with a single quote if they appear as the first character in a field value. | E15: 3 | F15: Compliant | G15: Automatically marked compliant from passing evidence: SQL injection regression and taint checks; SQL injection abuse-case regression. | H15: SR-09; AC-05; AbuseCaseRegressionTest; IastIntegrationTest | I15: Automatically inferred as implemented or justified from passing tests, source code, configuration, or build artifacts. | J15: Automated repository evidence | K15: AbuseCaseRegressionTest; IastIntegrationTest | L15: SQL injection regression and taint checks; SQL injection abuse-case regression | M15: Keep make asvs-tracker passing; reassess if code, tests, or scope changes.
A16: V1.3 | B16: Sanitization
A17: V1.3 | B17: Sanitization | C17: V1.3.1 | D17: Verify that all untrusted HTML input from WYSIWYG editors or similar is sanitized using a well-known and secure HTML sanitization library or framework feature. | E17: 1 | F17: N/A | G17: Automatically marked out of scope: No browser-rendered frontend surface is present in this repository. | H17: Automated scope inference | I17: Out of scope for VendNet as currently implemented, or the requirement does not apply to this REST API/backend. | J17: Scope inference | K17: Not required for current backend scope. | L17: No browser-rendered frontend surface is present in this repository. | M17: Revisit if the application scope changes.
A18: V1.3 | B18: Sanitization | C18: V1.3.2 | D18: Verify that the application avoids the use of eval() or other dynamic code execution features such as Spring Expression Language (SpEL). Where there is no alternative, any user input being included must be sanitized before being executed. | E18: 1 | F18: Compliant | G18: Automatically marked compliant from passing evidence: input shape/range validation; unknown-field rejection; payload/request limit coverage. | H18: SR-28; SR-29; SR-30; ControllerIntegrationTests; SystemFunctionalTests; ControllerUnitTests; GlobalExceptionHandlerTest; application.properties; Bean Validation and request-shape controls detected | I18: Automatically inferred as implemented or justified from passing tests, source code, configuration, or build artifacts. | J18: Automated repository evidence | K18: ControllerIntegrationTests; SystemFunctionalTests; ControllerUnitTests; GlobalExceptionHandlerTest; application.properties; Bean Validation and request-shape controls detected | L18: input shape/range validation; unknown-field rejection; payload/request limit coverage | M18: Keep make asvs-tracker passing; reassess if code, tests, or scope changes.
A19: V1.3 | B19: Sanitization | C19: V1.3.3 | D19: Verify that data being passed to a potentially dangerous context is sanitized beforehand to enforce safety measures, such as only allowing characters which are safe for this context and trimming input which is too long. | E19: 2 | F19: Compliant | G19: Automatically marked compliant from passing evidence: input shape/range validation; payload/request limit coverage; unknown-field rejection. | H19: SR-28; SR-30; SR-29; ControllerIntegrationTests; SystemFunctionalTests; application.properties; ControllerUnitTests; GlobalExceptionHandlerTest; Bean Validation and request-shape controls detected | I19: Automatically inferred as implemented or justified from passing tests, source code, configuration, or build artifacts. | J19: Automated repository evidence | K19: ControllerIntegrationTests; SystemFunctionalTests; application.properties; ControllerUnitTests; GlobalExceptionHandlerTest; Bean Validation and request-shape controls detected | L19: input shape/range validation; payload/request limit coverage; unknown-field rejection | M19: Keep make asvs-tracker passing; reassess if code, tests, or scope changes.
A20: V1.3 | B20: Sanitization | C20: V1.3.4 | D20: Verify that user-supplied Scalable Vector Graphics (SVG) scriptable content is validated or sanitized to contain only tags and attributes (such as draw graphics) that are safe for the application, e.g., do not contain scripts and foreignObject. | E20: 2 | F20: Planned | G20: Automatically marked planned because no direct implementation, test, or scope exemption matched this ASVS row. | H20: Automated inference found no strong repository evidence | I20: Automatically inferred as required or potentially relevant, but not yet proven by strong repository evidence. | J20: Evidence needed | K20: No direct automated evidence matched this ASVS row. | L20: ASVS row V1.3.4; level 2 | M20: Implement the control or add a targeted test/evidence rule, then rerun make asvs-tracker.
A21: V1.3 | B21: Sanitization | C21: V1.3.5 | D21: Verify that the application sanitizes or disables user-supplied scriptable or expression template language content, such as Markdown, CSS or XSL stylesheets, BBCode, or similar. | E21: 2 | F21: N/A | G21: Automatically marked out of scope: No browser-rendered frontend surface is present in this repository. | H21: Automated scope inference | I21: Out of scope for VendNet as currently implemented, or the requirement does not apply to this REST API/backend. | J21: Scope inference | K21: Not required for current backend scope. | L21: No browser-rendered frontend surface is present in this repository. | M21: Revisit if the application scope changes.
A22: V1.3 | B22: Sanitization | C22: V1.3.6 | D22: Verify that the application protects against Server-side Request Forgery (SSRF) attacks, by validating untrusted data against an allowlist of protocols, domains, paths and ports and sanitizing potentially dangerous characters before using the data to call another service. | E22: 2 | F22: N/A | G22: Automatically marked out of scope: No browser-rendered frontend surface is present in this repository. | H22: Automated scope inference | I22: Out of scope for VendNet as currently implemented, or the requirement does not apply to this REST API/backend. | J22: Scope inference | K22: Not required for current backend scope. | L22: No browser-rendered frontend surface is present in this repository. | M22: Revisit if the application scope changes.
A23: V1.3 | B23: Sanitization | C23: V1.3.7 | D23: Verify that the application protects against template injection attacks by not allowing templates to be built based on untrusted input. Where there is no alternative, any untrusted input being included dynamically during template creation must be sanitized or strictly validated. | E23: 2 | F23: Compliant | G23: Automatically marked compliant from passing evidence: input shape/range validation; unknown-field rejection; payload/request limit coverage; SQL injection regression and taint checks; SQL injection abuse-case regression. | H23: SR-28; SR-29; SR-30; SR-09; AC-05; ControllerIntegrationTests; SystemFunctionalTests; ControllerUnitTests; GlobalExceptionHandlerTest; application.properties; AbuseCaseRegressionTest; IastIntegrationTest; Bean Validation and request-shape controls detected | I23: Automatically inferred as implemented or justified from passing tests, source code, configuration, or build artifacts. | J23: Automated repository evidence | K23: ControllerIntegrationTests; SystemFunctionalTests; ControllerUnitTests; GlobalExceptionHandlerTest; application.properties; AbuseCaseRegressionTest; IastIntegrationTest; Bean Validation and request-shape controls detected | L23: input shape/range validation; unknown-field rejection; payload/request limit coverage; SQL injection regression and taint checks; SQL injection abuse-case regression | M23: Keep make asvs-tracker passing; reassess if code, tests, or scope changes.
A24: V1.3 | B24: Sanitization | C24: V1.3.8 | D24: Verify that the application appropriately sanitizes untrusted input before use in Java Naming and Directory Interface (JNDI) queries and that JNDI is configured securely to prevent JNDI injection attacks. | E24: 2 | F24: Compliant | G24: Automatically marked compliant from passing evidence: input shape/range validation; unknown-field rejection; payload/request limit coverage; SQL injection regression and taint checks; SQL injection abuse-case regression; path traversal and report sandboxing; unsafe path/link handling; path traversal abuse-case regression. | H24: SR-28; SR-29; SR-30; SR-09; AC-05; SR-26; SR-27; AC-06; ControllerIntegrationTests; SystemFunctionalTests; ControllerUnitTests; GlobalExceptionHandlerTest; application.properties; AbuseCaseRegressionTest; IastIntegrationTest; PathValidatorImplTest; ReportDirectoryServiceImplTest; Bean Validation and request-shape controls detected; path validation and report sandbox code detected | I24: Automatically inferred as implemented or justified from passing tests, source code, configuration, or build artifacts. | J24: Automated repository evidence | K24: ControllerIntegrationTests; SystemFunctionalTests; ControllerUnitTests; GlobalExceptionHandlerTest; application.properties; AbuseCaseRegressionTest; IastIntegrationTest; PathValidatorImplTest; ReportDirectoryServiceImplTest; Bean Validation and request-shape controls detected; path validation and report sandbox code detected | L24: input shape/range validation; unknown-field rejection; payload/request limit coverage; SQL injection regression and taint checks; SQL injection abuse-case regression; path traversal and report sandboxing; unsafe path/link handling; path traversal abuse-case regression | M24: Keep make asvs-tracker passing; reassess if code, tests, or scope changes.
A25: V1.3 | B25: Sanitization | C25: V1.3.9 | D25: Verify that the application sanitizes content before it is sent to memcache to prevent injection attacks. | E25: 2 | F25: Compliant | G25: Automatically marked compliant from passing evidence: SQL injection regression and taint checks; SQL injection abuse-case regression. | H25: SR-09; AC-05; AbuseCaseRegressionTest; IastIntegrationTest | I25: Automatically inferred as implemented or justified from passing tests, source code, configuration, or build artifacts. | J25: Automated repository evidence | K25: AbuseCaseRegressionTest; IastIntegrationTest | L25: SQL injection regression and taint checks; SQL injection abuse-case regression | M25: Keep make asvs-tracker passing; reassess if code, tests, or scope changes.
A26: V1.3 | B26: Sanitization | C26: V1.3.10 | D26: Verify that format strings which might resolve in an unexpected or malicious way when used are sanitized before being processed. | E26: 2 | F26: N/A | G26: Automatically marked out of scope: No user-controlled printf-style format-string execution path is present in the Java REST backend. | H26: Automated scope inference | I26: Out of scope for VendNet as currently implemented, or the requirement does not apply to this REST API/backend. | J26: Scope inference | K26: Not required for current backend scope. | L26: No user-controlled printf-style format-string execution path is present in the Java REST backend. | M26: Revisit if the application scope changes.
A27: V1.3 | B27: Sanitization | C27: V1.3.11 | D27: Verify that the application sanitizes user input before passing to mail systems to protect against SMTP or IMAP injection. | E27: 2 | F27: Compliant | G27: Automatically marked compliant from passing evidence: input shape/range validation; unknown-field rejection; payload/request limit coverage; SQL injection regression and taint checks; SQL injection abuse-case regression. | H27: SR-28; SR-29; SR-30; SR-09; AC-05; ControllerIntegrationTests; SystemFunctionalTests; ControllerUnitTests; GlobalExceptionHandlerTest; application.properties; AbuseCaseRegressionTest; IastIntegrationTest; Bean Validation and request-shape controls detected | I27: Automatically inferred as implemented or justified from passing tests, source code, configuration, or build artifacts. | J27: Automated repository evidence | K27: ControllerIntegrationTests; SystemFunctionalTests; ControllerUnitTests; GlobalExceptionHandlerTest; application.properties; AbuseCaseRegressionTest; IastIntegrationTest; Bean Validation and request-shape controls detected | L27: input shape/range validation; unknown-field rejection; payload/request limit coverage; SQL injection regression and taint checks; SQL injection abuse-case regression | M27: Keep make asvs-tracker passing; reassess if code, tests, or scope changes.
A28: V1.3 | B28: Sanitization | C28: V1.3.12 | D28: Verify that regular expressions are free from elements causing exponential backtracking, and ensure untrusted input is sanitized to mitigate ReDoS or Runaway Regex attacks. | E28: 3 | F28: Compliant | G28: Automatically marked compliant from passing evidence: path traversal and report sandboxing; input shape/range validation; unknown-field rejection; payload/request limit coverage. | H28: SR-26; SR-28; SR-29; SR-30; PathValidatorImplTest; ReportDirectoryServiceImplTest; AbuseCaseRegressionTest; ControllerIntegrationTests; SystemFunctionalTests; ControllerUnitTests; GlobalExceptionHandlerTest; application.properties; Bean Validation and request-shape controls detected; path validation and report sandbox code detected | I28: Automatically inferred as implemented or justified from passing tests, source code, configuration, or build artifacts. | J28: Automated repository evidence | K28: PathValidatorImplTest; ReportDirectoryServiceImplTest; AbuseCaseRegressionTest; ControllerIntegrationTests; SystemFunctionalTests; ControllerUnitTests; GlobalExceptionHandlerTest; application.properties; Bean Validation and request-shape controls detected; path validation and report sandbox code detected | L28: path traversal and report sandboxing; input shape/range validation; unknown-field rejection; payload/request limit coverage | M28: Keep make asvs-tracker passing; reassess if code, tests, or scope changes.
A29: V1.4 | B29: Memory, String, and Unmanaged Code
A30: V1.4 | B30: Memory, String, and Unmanaged Code | C30: V1.4.1 | D30: Verify that the application uses memory-safe string, safer memory copy and pointer arithmetic to detect or prevent stack, buffer, or heap overflows. | E30: 2 | F30: N/A | G30: Automatically marked out of scope: This is a managed JVM application without native pointer arithmetic or application-managed memory allocation. | H30: Automated scope inference | I30: Out of scope for VendNet as currently implemented, or the requirement does not apply to this REST API/backend. | J30: Scope inference | K30: Not required for current backend scope. | L30: This is a managed JVM application without native pointer arithmetic or application-managed memory allocation. | M30: Revisit if the application scope changes.
A31: V1.4 | B31: Memory, String, and Unmanaged Code | C31: V1.4.2 | D31: Verify that sign, range, and input validation techniques are used to prevent integer overflows. | E31: 2 | F31: Compliant | G31: Automatically marked compliant from passing evidence: stock limit validation; input shape/range validation; unknown-field rejection; payload/request limit coverage. | H31: SR-25; SR-28; SR-29; SR-30; SlotServiceTest; SaleServiceTest; ControllerIntegrationTests; SystemFunctionalTests; ControllerUnitTests; GlobalExceptionHandlerTest; application.properties; Bean Validation and request-shape controls detected | I31: Automatically inferred as implemented or justified from passing tests, source code, configuration, or build artifacts. | J31: Automated repository evidence | K31: SlotServiceTest; SaleServiceTest; ControllerIntegrationTests; SystemFunctionalTests; ControllerUnitTests; GlobalExceptionHandlerTest; application.properties; Bean Validation and request-shape controls detected | L31: stock limit validation; input shape/range validation; unknown-field rejection; payload/request limit coverage | M31: Keep make asvs-tracker passing; reassess if code, tests, or scope changes.
A32: V1.4 | B32: Memory, String, and Unmanaged Code | C32: V1.4.3 | D32: Verify that dynamically allocated memory and resources are released, and that references or pointers to freed memory are removed or set to null to prevent dangling pointers and use-after-free vulnerabilities. | E32: 2 | F32: N/A | G32: Automatically marked out of scope: This is a managed JVM application without native pointer arithmetic or application-managed memory allocation. | H32: Automated scope inference | I32: Out of scope for VendNet as currently implemented, or the requirement does not apply to this REST API/backend. | J32: Scope inference | K32: Not required for current backend scope. | L32: This is a managed JVM application without native pointer arithmetic or application-managed memory allocation. | M32: Revisit if the application scope changes.
A33: V1.5 | B33: Safe Deserialization
A34: V1.5 | B34: Safe Deserialization | C34: V1.5.1 | D34: Verify that the application configures XML parsers to use a restrictive configuration and that unsafe features such as resolving external entities are disabled to prevent XML eXternal Entity (XXE) attacks. | E34: 1 | F34: N/A | G34: Automatically marked out of scope: No XML/SOAP API surface is present; controllers return JSON REST responses. | H34: Automated scope inference | I34: Out of scope for VendNet as currently implemented, or the requirement does not apply to this REST API/backend. | J34: Scope inference | K34: Not required for current backend scope. | L34: No XML/SOAP API surface is present; controllers return JSON REST responses. | M34: Revisit if the application scope changes.
A35: V1.5 | B35: Safe Deserialization | C35: V1.5.2 | D35: Verify that deserialization of untrusted data enforces safe input handling, such as using an allowlist of object types or restricting client-defined object types, to prevent deserialization attacks. Deserialization mechanisms that are explicitly defined as insecure must not be used with untrusted input. | E35: 2 | F35: Compliant | G35: Automatically marked compliant from passing evidence: input shape/range validation; unknown-field rejection; payload/request limit coverage. | H35: SR-28; SR-29; SR-30; ControllerIntegrationTests; SystemFunctionalTests; ControllerUnitTests; GlobalExceptionHandlerTest; application.properties; Bean Validation and request-shape controls detected | I35: Automatically inferred as implemented or justified from passing tests, source code, configuration, or build artifacts. | J35: Automated repository evidence | K35: ControllerIntegrationTests; SystemFunctionalTests; ControllerUnitTests; GlobalExceptionHandlerTest; application.properties; Bean Validation and request-shape controls detected | L35: input shape/range validation; unknown-field rejection; payload/request limit coverage | M35: Keep make asvs-tracker passing; reassess if code, tests, or scope changes.
A36: V1.5 | B36: Safe Deserialization | C36: V1.5.3 | D36: Verify that different parsers used in the application for the same data type (e.g., JSON parsers, XML parsers, URL parsers), perform parsing in a consistent way and use the same character encoding mechanism to avoid issues such as JSON Interoperability vulnerabilities or different URI or file parsing behavior being exploited in Remote File Inclusion (RFI) or Server-side Request Forgery (SSRF) attacks. | E36: 3 | F36: N/A | G36: Automatically marked out of scope: No XML/SOAP API surface is present; controllers return JSON REST responses. | H36: Automated scope inference | I36: Out of scope for VendNet as currently implemented, or the requirement does not apply to this REST API/backend. | J36: Scope inference | K36: Not required for current backend scope. | L36: No XML/SOAP API surface is present; controllers return JSON REST responses. | M36: Revisit if the application scope changes.

Sheet V2 - Validation and Business Lo
A1: Section ID | B1: Section Name | C1: Req ID | D1: Description | E1: Level | F1: Status | G1: Observations | H1: Reference / Link | I1: DX Status Meaning | J1: Evidence Type | K1: Automated Evidence | L1: Evidence Source | M1: Next Action
A2: V2.1 | B2: Validation and Business Logic Documentation
A3: V2.1 | B3: Validation and Business Logic Documentation | C3: V2.1.1 | D3: Verify that the application's documentation defines input validation rules for how to check the validity of data items against an expected structure. This could be common data formats such as credit card numbers, email addresses, telephone numbers, or it could be an internal data format. | E3: 1 | F3: Compliant | G3: Automatically marked compliant from passing evidence: server-side price enforcement; pagination/large-response controls; input shape/range validation; unknown-field rejection; payload/request limit coverage. | H3: SR-24; SR-31; SR-28; SR-29; SR-30; SaleServiceTest; AbuseCaseRegressionTest; ControllerIntegrationTests; SystemFunctionalTests; ControllerUnitTests; GlobalExceptionHandlerTest; application.properties; Bean Validation and request-shape controls detected | I3: Automatically inferred as implemented or justified from passing tests, source code, configuration, or build artifacts. | J3: Automated repository evidence | K3: SaleServiceTest; AbuseCaseRegressionTest; ControllerIntegrationTests; SystemFunctionalTests; ControllerUnitTests; GlobalExceptionHandlerTest; application.properties; Bean Validation and request-shape controls detected | L3: server-side price enforcement; pagination/large-response controls; input shape/range validation; unknown-field rejection; payload/request limit coverage | M3: Keep make asvs-tracker passing; reassess if code, tests, or scope changes.
A4: V2.1 | B4: Validation and Business Logic Documentation | C4: V2.1.2 | D4: Verify that the application's documentation defines how to validate the logical and contextual consistency of combined data items, such as checking that suburb and ZIP code match. | E4: 2 | F4: Compliant | G4: Automatically marked compliant from passing evidence: stock limit validation; input shape/range validation; unknown-field rejection; payload/request limit coverage; authentication audit logging; sensitive log data checks; safe error response checks. | H4: SR-25; SR-28; SR-29; SR-30; SR-37; SR-45; SR-46; SlotServiceTest; SaleServiceTest; ControllerIntegrationTests; SystemFunctionalTests; ControllerUnitTests; GlobalExceptionHandlerTest; application.properties; AuthServiceTest; AuditLoggerTest; Bean Validation and request-shape controls detected; audit logging implementation detected; centralized safe error handling detected | I4: Automatically inferred as implemented or justified from passing tests, source code, configuration, or build artifacts. | J4: Automated repository evidence | K4: SlotServiceTest; SaleServiceTest; ControllerIntegrationTests; SystemFunctionalTests; ControllerUnitTests; GlobalExceptionHandlerTest; application.properties; AuthServiceTest; AuditLoggerTest; Bean Validation and request-shape controls detected; audit logging implementation detected; centralized safe error handling detected | L4: stock limit validation; input shape/range validation; unknown-field rejection; payload/request limit coverage; authentication audit logging; sensitive log data checks; safe error response checks | M4: Keep make asvs-tracker passing; reassess if code, tests, or scope changes.
A5: V2.1 | B5: Validation and Business Logic Documentation | C5: V2.1.3 | D5: Verify that expectations for business logic limits and validations are documented, including both per-user and globally across the application. | E5: 2 | F5: Compliant | G5: Automatically marked compliant from passing evidence: administrator MFA; safe error response checks; input shape/range validation; unknown-field rejection; payload/request limit coverage; transaction and stock consistency; server-side price enforcement; stock limit validation; client-supplied price abuse-case regression; TOCTOU/stock race abuse-case regression; authentication audit logging; sensitive log data checks. | H5: NFR-01; NFR-15; SR-01; SR-46; SR-28; SR-29; SR-30; SR-15; SR-24; SR-25; AC-03; AC-07; SR-37; SR-45; AuthServiceTest; AuthControllerIntegrationTest; GlobalExceptionHandlerTest; ControllerIntegrationTests; SystemFunctionalTests; ControllerUnitTests; application.properties; SaleServiceTest; SlotServiceTest; AbuseCaseRegressionTest; AuditLoggerTest; MFA/TOTP code and tests detected; Bean Validation and request-shape controls detected; audit logging implementation detected; centralized safe error handling detected | I5: Automatically inferred as implemented or justified from passing tests, source code, configuration, or build artifacts. | J5: Automated repository evidence | K5: AuthServiceTest; AuthControllerIntegrationTest; GlobalExceptionHandlerTest; ControllerIntegrationTests; SystemFunctionalTests; ControllerUnitTests; application.properties; SaleServiceTest; SlotServiceTest; AbuseCaseRegressionTest; AuditLoggerTest; MFA/TOTP code and tests detected; Bean Validation and request-shape controls detected; audit logging implementation detected; centralized safe error handling detected | L5: administrator MFA; safe error response checks; input shape/range validation; unknown-field rejection; payload/request limit coverage; transaction and stock consistency; server-side price enforcement; stock limit validation; client-supplied price abuse-case regression; TOCTOU/stock race abuse-case regression; authentication audit logging; sensitive log data checks | M5: Keep make asvs-tracker passing; reassess if code, tests, or scope changes.
A6: V2.2 | B6: Input Validation
A7: V2.2 | B7: Input Validation | C7: V2.2.1 | D7: Verify that input is validated to enforce business or functional expectations for that input. This should either use positive validation against an allow list of values, patterns, and ranges, or be based on comparing the input to an expected structure and logical limits according to predefined rules. For L1, this can focus on input which is used to make specific business or security decisions. For L2 and up, this should apply to all input. | E7: 1 | F7: Compliant | G7: Automatically marked compliant from passing evidence: server-side price enforcement; stock limit validation; path traversal and report sandboxing; input shape/range validation; unknown-field rejection; payload/request limit coverage; pagination/large-response controls; authentication audit logging; sensitive log data checks; safe error response checks. | H7: SR-24; SR-25; SR-26; SR-28; SR-29; SR-30; SR-31; SR-37; SR-45; SR-46; SaleServiceTest; AbuseCaseRegressionTest; SlotServiceTest; PathValidatorImplTest; ReportDirectoryServiceImplTest; ControllerIntegrationTests; SystemFunctionalTests; ControllerUnitTests; GlobalExceptionHandlerTest; application.properties; AuthServiceTest; AuditLoggerTest; Bean Validation and request-shape controls detected; path validation and report sandbox code detected; audit logging implementation detected; centralized safe error handling detected | I7: Automatically inferred as implemented or justified from passing tests, source code, configuration, or build artifacts. | J7: Automated repository evidence | K7: SaleServiceTest; AbuseCaseRegressionTest; SlotServiceTest; PathValidatorImplTest; ReportDirectoryServiceImplTest; ControllerIntegrationTests; SystemFunctionalTests; ControllerUnitTests; GlobalExceptionHandlerTest; application.properties; AuthServiceTest; AuditLoggerTest; Bean Validation and request-shape controls detected; path validation and report sandbox code detected; audit logging implementation detected; centralized safe error handling detected | L7: server-side price enforcement; stock limit validation; path traversal and report sandboxing; input shape/range validation; unknown-field rejection; payload/request limit coverage; pagination/large-response controls; authentication audit logging; sensitive log data checks; safe error response checks | M7: Keep make asvs-tracker passing; reassess if code, tests, or scope changes.
A8: V2.2 | B8: Input Validation | C8: V2.2.2 | D8: Verify that the application is designed to enforce input validation at a trusted service layer. While client-side validation improves usability and should be encouraged, it must not be relied upon as a security control. | E8: 1 | F8: Compliant | G8: Automatically marked compliant from passing evidence: server-side price enforcement; stock limit validation; input shape/range validation; unknown-field rejection; payload/request limit coverage. | H8: SR-24; SR-25; SR-28; SR-29; SR-30; SaleServiceTest; AbuseCaseRegressionTest; SlotServiceTest; ControllerIntegrationTests; SystemFunctionalTests; ControllerUnitTests; GlobalExceptionHandlerTest; application.properties; Bean Validation and request-shape controls detected | I8: Automatically inferred as implemented or justified from passing tests, source code, configuration, or build artifacts. | J8: Automated repository evidence | K8: SaleServiceTest; AbuseCaseRegressionTest; SlotServiceTest; ControllerIntegrationTests; SystemFunctionalTests; ControllerUnitTests; GlobalExceptionHandlerTest; application.properties; Bean Validation and request-shape controls detected | L8: server-side price enforcement; stock limit validation; input shape/range validation; unknown-field rejection; payload/request limit coverage | M8: Keep make asvs-tracker passing; reassess if code, tests, or scope changes.
A9: V2.2 | B9: Input Validation | C9: V2.2.3 | D9: Verify that the application ensures that combinations of related data items are reasonable according to the pre-defined rules. | E9: 2 | F9: Compliant | G9: Automatically marked compliant from passing evidence: transaction and stock consistency; stock limit validation; input shape/range validation; unknown-field rejection; payload/request limit coverage. | H9: SR-15; SR-25; SR-28; SR-29; SR-30; SaleServiceTest; SlotServiceTest; AbuseCaseRegressionTest; ControllerIntegrationTests; SystemFunctionalTests; ControllerUnitTests; GlobalExceptionHandlerTest; application.properties; Bean Validation and request-shape controls detected | I9: Automatically inferred as implemented or justified from passing tests, source code, configuration, or build artifacts. | J9: Automated repository evidence | K9: SaleServiceTest; SlotServiceTest; AbuseCaseRegressionTest; ControllerIntegrationTests; SystemFunctionalTests; ControllerUnitTests; GlobalExceptionHandlerTest; application.properties; Bean Validation and request-shape controls detected | L9: transaction and stock consistency; stock limit validation; input shape/range validation; unknown-field rejection; payload/request limit coverage | M9: Keep make asvs-tracker passing; reassess if code, tests, or scope changes.
A10: V2.3 | B10: Business Logic Security
A11: V2.3 | B11: Business Logic Security | C11: V2.3.1 | D11: Verify that the application will only process business logic flows for the same user in the expected sequential step order and without skipping steps. | E11: 1 | F11: Compliant | G11: Automatically marked compliant from passing evidence: input shape/range validation; unknown-field rejection; payload/request limit coverage; transaction and stock consistency; server-side price enforcement; stock limit validation; client-supplied price abuse-case regression; TOCTOU/stock race abuse-case regression; authentication audit logging; sensitive log data checks; safe error response checks. | H11: SR-28; SR-29; SR-30; SR-15; SR-24; SR-25; AC-03; AC-07; SR-37; SR-45; SR-46; ControllerIntegrationTests; SystemFunctionalTests; ControllerUnitTests; GlobalExceptionHandlerTest; application.properties; SaleServiceTest; SlotServiceTest; AbuseCaseRegressionTest; AuthServiceTest; AuditLoggerTest; Bean Validation and request-shape controls detected; audit logging implementation detected; centralized safe error handling detected | I11: Automatically inferred as implemented or justified from passing tests, source code, configuration, or build artifacts. | J11: Automated repository evidence | K11: ControllerIntegrationTests; SystemFunctionalTests; ControllerUnitTests; GlobalExceptionHandlerTest; application.properties; SaleServiceTest; SlotServiceTest; AbuseCaseRegressionTest; AuthServiceTest; AuditLoggerTest; Bean Validation and request-shape controls detected; audit logging implementation detected; centralized safe error handling detected | L11: input shape/range validation; unknown-field rejection; payload/request limit coverage; transaction and stock consistency; server-side price enforcement; stock limit validation; client-supplied price abuse-case regression; TOCTOU/stock race abuse-case regression; authentication audit logging; sensitive log data checks; safe error response checks | M11: Keep make asvs-tracker passing; reassess if code, tests, or scope changes.
A12: V2.3 | B12: Business Logic Security | C12: V2.3.2 | D12: Verify that business logic limits are implemented per the application's documentation to avoid business logic flaws being exploited. | E12: 2 | F12: Compliant | G12: Automatically marked compliant from passing evidence: server-side price enforcement; stock limit validation; input shape/range validation; unknown-field rejection; payload/request limit coverage; transaction and stock consistency; client-supplied price abuse-case regression; TOCTOU/stock race abuse-case regression; authentication audit logging; sensitive log data checks; safe error response checks. | H12: SR-24; SR-25; SR-28; SR-29; SR-30; SR-15; AC-03; AC-07; SR-37; SR-45; SR-46; SaleServiceTest; AbuseCaseRegressionTest; SlotServiceTest; ControllerIntegrationTests; SystemFunctionalTests; ControllerUnitTests; GlobalExceptionHandlerTest; application.properties; AuthServiceTest; AuditLoggerTest; Bean Validation and request-shape controls detected; audit logging implementation detected; centralized safe error handling detected | I12: Automatically inferred as implemented or justified from passing tests, source code, configuration, or build artifacts. | J12: Automated repository evidence | K12: SaleServiceTest; AbuseCaseRegressionTest; SlotServiceTest; ControllerIntegrationTests; SystemFunctionalTests; ControllerUnitTests; GlobalExceptionHandlerTest; application.properties; AuthServiceTest; AuditLoggerTest; Bean Validation and request-shape controls detected; audit logging implementation detected; centralized safe error handling detected | L12: server-side price enforcement; stock limit validation; input shape/range validation; unknown-field rejection; payload/request limit coverage; transaction and stock consistency; client-supplied price abuse-case regression; TOCTOU/stock race abuse-case regression; authentication audit logging; sensitive log data checks; safe error response checks | M12: Keep make asvs-tracker passing; reassess if code, tests, or scope changes.
A13: V2.3 | B13: Business Logic Security | C13: V2.3.3 | D13: Verify that transactions are being used at the business logic level such that either a business logic operation succeeds in its entirety or it is rolled back to the previous correct state. | E13: 2 | F13: Compliant | G13: Automatically marked compliant from passing evidence: transaction and stock consistency; input shape/range validation; unknown-field rejection; payload/request limit coverage; server-side price enforcement; stock limit validation; client-supplied price abuse-case regression; TOCTOU/stock race abuse-case regression; authentication audit logging; sensitive log data checks; safe error response checks. | H13: NFR-08; SR-15; SR-28; SR-29; SR-30; SR-24; SR-25; AC-03; AC-07; SR-37; SR-45; SR-46; SaleServiceTest; SlotServiceTest; AbuseCaseRegressionTest; ControllerIntegrationTests; SystemFunctionalTests; ControllerUnitTests; GlobalExceptionHandlerTest; application.properties; AuthServiceTest; AuditLoggerTest; Bean Validation and request-shape controls detected; audit logging implementation detected; centralized safe error handling detected | I13: Automatically inferred as implemented or justified from passing tests, source code, configuration, or build artifacts. | J13: Automated repository evidence | K13: SaleServiceTest; SlotServiceTest; AbuseCaseRegressionTest; ControllerIntegrationTests; SystemFunctionalTests; ControllerUnitTests; GlobalExceptionHandlerTest; application.properties; AuthServiceTest; AuditLoggerTest; Bean Validation and request-shape controls detected; audit logging implementation detected; centralized safe error handling detected | L13: transaction and stock consistency; input shape/range validation; unknown-field rejection; payload/request limit coverage; server-side price enforcement; stock limit validation; client-supplied price abuse-case regression; TOCTOU/stock race abuse-case regression; authentication audit logging; sensitive log data checks; safe error response checks | M13: Keep make asvs-tracker passing; reassess if code, tests, or scope changes.
